<?xml version="1.0" ?>
<sdf version="1.8">

  <!--
    Определяем мир (world) под названием "Moving_robot". 
    Внутри указываем параметры физики, плагины для симуляции, освещение (sun) и объекты (models).
  -->
  <world name="Moving_robot">

    <!--
      physics type="ignored" — в некоторых версиях Ignition/Gazebo физика может задаваться 
      через системные плагины. Параметры:
        - max_step_size: максимальный шаг интеграции
        - real_time_factor: желаемая скорость реального времени (1.0 = реальное)
    -->
    <physics name="1ms" type="ignored">
      <max_step_size>0.001</max_step_size>
      <real_time_factor>1.0</real_time_factor>
    </physics>

    <!--
      Подключение базовых системных плагинов:
      1) gz-sim-physics-system: для управления физическими контактами
      2) gz-sim-user-commands-system: для пользовательских команд (например, spawn, remove)
      3) gz-sim-scene-broadcaster-system: для отображения сцены (3D-графика)
    -->
    <plugin filename="gz-sim-physics-system" name="gz::sim::systems::Physics"/>
    	<plugin
		filename="gz-sim-sensors-system"
		name="gz::sim::systems::Sensors">
	  <!-- Обычно указывают движок рендеринга -->
	  <render_engine>ogre2</render_engine>
	</plugin>
    <plugin filename="gz-sim-user-commands-system" name="gz::sim::systems::UserCommands"/>
    <plugin filename="gz-sim-scene-broadcaster-system" name="gz::sim::systems::SceneBroadcaster"/>

    <!--
      Настраиваем источник света "sun" (солнечный свет) с заданным направлением,
      интенсивностью (diffuse, specular) и другими параметрами.
    -->
    <light type="directional" name="sun">
      <cast_shadows>true</cast_shadows>
      <pose>0 0 10 0 0 0</pose>
      <diffuse>0.8 0.8 0.8 1</diffuse>
      <specular>0.2 0.2 0.2 1</specular>
      <attenuation>
        <range>1000</range>
        <constant>0.9</constant>
        <linear>0.01</linear>
        <quadratic>0.001</quadratic>
      </attenuation>
      <direction>-0.5 0.1 -0.9</direction>
    </light>

    <!--
      Создаём "землю" (ground_plane) — большая плоскость для пола.
      static=true означает, что объект не участвует в движении, он статичен.
    -->
    <model name="ground_plane">
      <static>true</static>
      <link name="link">
        <collision name="collision">
          <geometry>
            <plane>
              <normal>0 0 1</normal>
            </plane>
          </geometry>
        </collision>
        <visual name="visual">
          <geometry>
            <plane>
              <normal>0 0 1</normal>
              <size>6 10</size>
            </plane>
          </geometry>
          <material>
            <ambient>0.8 0.8 0.8 1</ambient>
            <diffuse>0.8 0.8 0.8 1</diffuse>
            <specular>0.8 0.8 0.8 1</specular>
          </material>
        </visual>
      </link>
    </model>

    <!--
      Модель робота: "my_robot". У него корневым звеном (canonical_link) выступает "chassis".
      pose relative_to='world' означает, что робот будет размещён в абсолютных координатах.
    -->
    <model name='my_robot' canonical_link='chassis'>
      <pose relative_to='world'>-2 4 0 0 0 0</pose>

      <!--
        Основное звено: chassis (шасси).
        pose relative_to='__model__' => смещение внутри модели.
        inertial -> массо-инерционные характеристики.
        visual -> геометрия (box), цвет (синий).
        collision -> упрощённая геометрия для физ. столкновений.
      -->
      <link name='chassis'>
        <pose relative_to='__model__'>0 0 0.1 0 0 0</pose>
        <inertial>
          <mass>25</mass>
          <inertia>
            <ixx>0.126164</ixx>
            <ixy>0</ixy>
            <ixz>0</ixz>
            <iyy>0.416519</iyy>
            <iyz>0</iyz>
            <izz>0.481014</izz>
          </inertia>
        </inertial>
        <visual name='visual'>
          <geometry>
            <box>
              <size>0.24 0.14 0.03</size>
            </box>
          </geometry>
          <material>
            <ambient>0.0 0.0 1.0 1</ambient>
            <diffuse>0.0 0.0 1.0 1</diffuse>
            <specular>0.0 0.0 1.0 1</specular>
          </material>
        </visual>
        <collision name='collision'>
          <!-- collision важна для реакций физики (сталкивание с объектами) -->
          <geometry>
            <box>
              <size>0.24 0.14 0.03</size>
            </box>
          </geometry>
        </collision>
      </link>
      <!--
        Левое колесо (left_wheel).
        pose relative_to='chassis' -> 0.05 м вперёд, 0.10 м вправо, 
        поворот -1.5707 рад (примерно -90 градусов) вокруг оси X, 
        чтобы цилиндр лежал в нужной плоскости.
      -->
      <link name='left_wheel'>
        <pose relative_to="chassis">0.06 0.04 -0.015 -1.5707 0 0</pose>
        <inertial>
          <mass>2.5</mass>
          <inertia>
            <ixx>0.145833</ixx>
            <ixy>0</ixy>
            <ixz>0</ixz>
            <iyy>0.145833</iyy>
            <iyz>0</iyz>
            <izz>0.125</izz>
          </inertia>
        </inertial>
        <visual name='visual'>
          <geometry>
            <cylinder>
              <radius>0.0335</radius>
              <length>0.025</length>
            </cylinder>
          </geometry>
          <material>
            <ambient>1.0 0.0 0.0 1</ambient>
            <diffuse>1.0 0.0 0.0 1</diffuse>
            <specular>1.0 0.0 0.0 1</specular>
          </material>
        </visual>
        <collision name='collision'>
          <geometry>
            <cylinder>
              <radius>0.0335</radius>
              <length>0.025</length>
            </cylinder>
          </geometry>
        </collision>
      </link>

      <!--
        Правое колесо (right_wheel).
        Аналогично левому, только y=-.
      -->
      <link name='right_wheel'>
        <pose relative_to="chassis">0.06 -0.04 -0.015 -1.5707 0 0</pose>
        <inertial>
          <mass>2.5</mass>
          <inertia>
            <ixx>0.145833</ixx>
            <ixy>0</ixy>
            <ixz>0</ixz>
            <iyy>0.145833</iyy>
            <iyz>0</iyz>
            <izz>0.125</izz>
          </inertia>
        </inertial>
        <visual name='visual'>
          <geometry>
            <cylinder>
              <radius>0.0335</radius>
              <length>0.025</length>
            </cylinder>
          </geometry>
          <material>
            <ambient>1.0 0.0 0.0 1</ambient>
            <diffuse>1.0 0.0 0.0 1</diffuse>
            <specular>1.0 0.0 0.0 1</specular>
          </material>
        </visual>
        <collision name='collision'>
          <geometry>
            <cylinder>
              <radius>0.0335</radius>
              <length>0.025</length>
            </cylinder>
          </geometry>
        </collision>
      </link>

	  
      <!--
        frame "caster_frame" привязан к шасси (chassis). 
        Это точка, к которой затем крепится link caster (шарообразная опора).
      -->
      <!--
        Кастер (caster) - задний опорный шарик. 
        Расположен на frame="caster_frame". 
        Масса, инерция - условные.
      -->
      

      <!--
        floor1 - "первый этаж" (промежуточная платформа),
        поднят над шасси на 0.065 м.
        Масса и габариты - условные.
      -->
      
	
	<frame name="caster_frame" attached_to='chassis'>
        <pose>-0.06 0 -0.015 0 0 0</pose>
      </frame>
	  
	  <link name='caster'>
        <pose relative_to='caster_frame'/>
        <inertial>
          <mass>6</mass>
          <inertia>
            <ixx>0.1</ixx>
            <ixy>0</ixy>
            <ixz>0</ixz>
            <iyy>0.1</iyy>
            <iyz>0</iyz>
            <izz>0.1</izz>
          </inertia>
        </inertial>
        <visual name='visual'>
          <geometry>
            <sphere>
              <radius>0.0335</radius>
            </sphere>
          </geometry>
          <material>
            <ambient>0.0 1 0.0 1</ambient>
            <diffuse>0.0 1 0.0 1</diffuse>
            <specular>0.0 1 0.0 1</specular>
          </material>
        </visual>
        <collision name='collision'>
          <geometry>
            <sphere>
              <radius>0.0335</radius>
            </sphere>
          </geometry>
        </collision>
      </link>
	  
	<joint name='caster_wheel' type='ball'>
        <parent>chassis</parent>
        <child>caster</child>
      </joint>
      <!--
        lidar_link - цилиндр, имитирующий 2D-лидар.
        Расположен на +0.04 над floor2.
      -->

      <!--
        Ось вращения левого колеса (left_wheel_joint) - revolute.
        joint подключает parent=chassis, child=left_wheel.
      -->
      <joint name='left_wheel_joint' type='revolute'>
        <pose relative_to='left_wheel'/>
        <parent>chassis</parent>
        <child>left_wheel</child>
        <axis>
          <xyz expressed_in='__model__'>0 1 0</xyz>
          <limit>
            <lower>-1.79769e+308</lower>
            <upper>1.79769e+308</upper>
          </limit>
        </axis>
      </joint>
	
      <!--
        Аналогично для правого колеса (right_wheel_joint).
      -->
      <joint name='right_wheel_joint' type='revolute'>
        <pose relative_to='right_wheel'/>
        <parent>chassis</parent>
        <child>right_wheel</child>
        <axis>
          <xyz expressed_in='__model__'>0 1 0</xyz>
          <limit>
            <lower>-1.79769e+308</lower>
            <upper>1.79769e+308</upper>
          </limit>
        </axis>
      </joint>
	
		
      <!--
        Четыре стойки (cylinders) радиусом 0.005, 
        длиной 0.195, расположены по углам базы:
        (0.09, 0.09), (0.09, -0.09), (-0.09, 0.09), (-0.09, -0.09).
        Каждая с фиксированным joint.
      -->
      <!-- Передняя левая стойка -->
      

      <!--
        Соединение caster'а (задний шар) с шасси через шаровой joint (type='ball').
      -->

      <!--
        DiffDrive плагин для управления колесами:
        - left_joint / right_joint — названия суставов
        - wheel_separation / wheel_radius — основные геом. параметры
        - topic='cmd_vel' — команда на движение
      -->
      <link name="lidar_link">
        <pose relative_to="chassis">0 0 0.1 0 0 0</pose>
        <inertial>
          <mass>0.2</mass>
          <inertia>
            <ixx>0.001</ixx>
            <ixy>0</ixy>
            <ixz>0</ixz>
            <iyy>0.001</iyy>
            <iyz>0</iyz>
            <izz>0.001</izz>
          </inertia>
        </inertial>
        <visual name="lidar_visual">
          <geometry>
            <cylinder>
              <radius>0.035</radius>
              <length>0.025</length>
            </cylinder>
          </geometry>
          <material>
            <ambient>0 0  0  1</ambient>
            <diffuse>0  0  0  1</diffuse>
          </material>
        </visual>
		<sensor name="lidar_sensor" type="gpu_ray">
		  <frame_id>lidar_link</frame_id>
		  <pose>0 0 0.1 0 0 0</pose>
		  <topic>/scan</topic>
		  <update_rate>5</update_rate>
		  <ray>
			<scan>
			  <horizontal>
				<samples>360</samples>
				<resolution>1</resolution>
				<min_angle>-3.14</min_angle> <!-- -90° -->
				<max_angle>3.14</max_angle>  <!-- +90° -->
			  </horizontal>
			  <vertical>
				<samples>1</samples>
				<resolution>0.01</resolution>
				<min_angle>0</min_angle>
				<max_angle>0</max_angle>
			  </vertical>
			</scan>
			<range>
			  <min>0.08</min>
			  <max>10.0</max>
			  <resolution>0.01</resolution>
			</range>
			<noise>
			  <type>gaussian</type>
			  <mean>0.0</mean>
			  <stddev>0.01</stddev>
			</noise>
		  </ray>
		  <always_on>true</always_on>
		  <visualize>true</visualize>
		</sensor>
        <collision name="lidar_collision">
          <geometry>
            <cylinder>
              <radius>0.035</radius>
              <length>0.05</length>
            </cylinder>
          </geometry>
        </collision>
      </link>
      <joint name="lidar_joint" type="fixed">
        <parent>chassis</parent>
        <child>lidar_link</child>
      </joint>
      <plugin filename="gz-sim-diff-drive-system" name="gz::sim::systems::DiffDrive">
        <left_joint>left_wheel_joint</left_joint>
        <right_joint>right_wheel_joint</right_joint>
        <wheel_separation>0.08</wheel_separation>
        <wheel_radius>0.0335</wheel_radius>
        <odom_publish_frequency>50</odom_publish_frequency>
        <topic>cmd_vel</topic>
        <wheel_slip>0.05</wheel_slip>
      </plugin>
    </model>

  
  
	<model name="white_wall1">
	    <static>true</static>
      <pose>0 5 0 0 0 0</pose>
      <link name="cube_link">
        <visual name="visual">
          <geometry>
            <box>
              <size>6 0.2 3</size>
            </box>
          </geometry>
          <material>
            <ambient>1 1 1 1</ambient>
            <diffuse>1 1 1 1</diffuse>
            <specular>1 1 1 1</specular>
          </material>
        </visual>
        <collision name="collision">
          <geometry>
            <box>
              <size>6 0.2 3</size>
            </box>
          </geometry>
        </collision>
      </link>
    </model>
	
	<model name="white_wall2">
	    <static>true</static>
      <pose>0 -5 0 0 0 0</pose>
      <link name="cube_link">
        <visual name="visual">
          <geometry>
            <box>
              <size>6 0.2 3</size>
            </box>
          </geometry>
          <material>
            <ambient>1 1 1 1</ambient>
            <diffuse>1 1 1 1</diffuse>
            <specular>1 1 1 1</specular>
          </material>
        </visual>
        <collision name="collision">
          <geometry>
            <box>
              <size>6 0.2 3</size>
            </box>
          </geometry>
        </collision>
      </link>
    </model>
	
	<model name="white_wall3">
	    <static>true</static>
      <pose>3 0 0 0 0 0</pose>
      <link name="cube_link">
        <visual name="visual">
          <geometry>
            <box>
              <size>0.2 10 3</size>
            </box>
          </geometry>
          <material>
            <ambient>1 1 1 1</ambient>
            <diffuse>1 1 1 1</diffuse>
            <specular>1 1 1 1</specular>
          </material>
        </visual>
        <collision name="collision">
          <geometry>
            <box>
              <size>0.2 10 3</size>
            </box>
          </geometry>
        </collision>
      </link>
    </model>
	
	<model name="white_wall4">
	    <static>true</static>
      <pose>-1 2 0.025 0 0 0</pose>
      <link name="cube_link">
        <visual name="visual">
          <geometry>
            <box>
              <size>4.5 0.2 3</size>
            </box>
          </geometry>
          <material>
            <ambient>1 1 1 1</ambient>
            <diffuse>1 1 1 1</diffuse>
            <specular>1 1 1 1</specular>
          </material>
        </visual>
        <collision name="collision">
          <geometry>
            <box>
              <size>4.5 0.2 3</size>
            </box>
          </geometry>
        </collision>
      </link>
    </model>
	
	<model name="white_wall5">
	    <static>true</static>
      <pose>-3 0 0 0 0 0</pose>
      <link name="cube_link">
        <visual name="visual">
          <geometry>
            <box>
              <size>0.2 10 3</size>
            </box>
          </geometry>
          <material>
            <ambient>1 1 1 1</ambient>
            <diffuse>1 1 1 1</diffuse>
            <specular>1 1 1 1</specular>
          </material>
        </visual>
        <collision name="collision">
          <geometry>
            <box>
              <size>0.2 10 3</size>
            </box>
          </geometry>
        </collision>
      </link>
    </model>
	
	<model name="white_wall6">
	    <static>true</static>
      <pose>-1 -1 0.025 0 0 0</pose>
      <link name="cube_link">
        <visual name="visual">
          <geometry>
            <box>
              <size>4.5 0.2 3</size>
            </box>
          </geometry>
          <material>
            <ambient>1 1 1 1</ambient>
            <diffuse>1 1 1 1</diffuse>
            <specular>1 1 1 1</specular>
          </material>
        </visual>
        <collision name="collision">
          <geometry>
            <box>
              <size>4.5 0.2 3</size>
            </box>
          </geometry>
        </collision>
      </link>
    </model>
    
    <model name="white_wall7">
	    <static>true</static>
      <pose>1.4 -3 0.025 0 0 0</pose>
      <link name="cube_link">
        <visual name="visual">
          <geometry>
            <box>
              <size>2.8 0.2 3</size>
            </box>
          </geometry>
          <material>
            <ambient>1 1 1 1</ambient>
            <diffuse>1 1 1 1</diffuse>
            <specular>1 1 1 1</specular>
          </material>
        </visual>
        <collision name="collision">
          <geometry>
            <box>
              <size>2.8 0.2 3</size>
            </box>
          </geometry>
        </collision>
      </link>
    </model>
    
    <model name="white_wall8">
	    <static>true</static>
      <pose>0 -4 0.025 0 0 0</pose>
      <link name="cube_link">
        <visual name="visual">
          <geometry>
            <box>
              <size>0.2 2 3</size>
            </box>
          </geometry>
          <material>
            <ambient>1 1 1 1</ambient>
            <diffuse>1 1 1 1</diffuse>
            <specular>1 1 1 1</specular>
          </material>
        </visual>
        <collision name="collision">
          <geometry>
            <box>
              <size>0.2 2 3</size>
            </box>
          </geometry>
        </collision>
      </link>
    </model>
    
    <model name="white_wall9">
	    <static>true</static>
      <pose>1 1 0.025 0 0 0</pose>
      <link name="cube_link">
        <visual name="visual">
          <geometry>
            <box>
              <size>0.2 1.8 3</size>
            </box>
          </geometry>
          <material>
            <ambient>1 1 1 1</ambient>
            <diffuse>1 1 1 1</diffuse>
            <specular>1 1 1 1</specular>
          </material>
        </visual>
        <collision name="collision">
          <geometry>
            <box>
              <size>0.2 1.8 3</size>
            </box>
          </geometry>
        </collision>
      </link>
    </model>
    
    <model name="white_wall10">
	    <static>true</static>
      <pose>1 -0.9 0.025 0 0 0</pose>
      <link name="cube_link">
        <visual name="visual">
          <geometry>
            <box>
              <size>0.2 0.2 3</size>
            </box>
          </geometry>
          <material>
            <ambient>1 1 1 1</ambient>
            <diffuse>1 1 1 1</diffuse>
            <specular>1 1 1 1</specular>
          </material>
        </visual>
        <collision name="collision">
          <geometry>
            <box>
              <size>0.2 0.2 3</size>
            </box>
          </geometry>
        </collision>
      </link>
    </model>
    
    <model name="white_wall11">
	    <static>true</static>
      <pose>2.8 2 0.025 0 0 0</pose>
      <link name="cube_link">
        <visual name="visual">
          <geometry>
            <box>
              <size>0.5 0.2 3</size>
            </box>
          </geometry>
          <material>
            <ambient>1 1 1 1</ambient>
            <diffuse>1 1 1 1</diffuse>
            <specular>1 1 1 1</specular>
          </material>
        </visual>
        <collision name="collision">
          <geometry>
            <box>
              <size>0.5 0.2 3</size>
            </box>
          </geometry>
        </collision>
      </link>
    </model>
    
    <model name="white_wall12">
	    <static>true</static>
      <pose>2.8 -1 0.025 0 0 0</pose>
      <link name="cube_link">
        <visual name="visual">
          <geometry>
            <box>
              <size>0.5 0.2 3</size>
            </box>
          </geometry>
          <material>
            <ambient>1 1 1 1</ambient>
            <diffuse>1 1 1 1</diffuse>
            <specular>1 1 1 1</specular>
          </material>
        </visual>
        <collision name="collision">
          <geometry>
            <box>
              <size>0.5 0.2 3</size>
            </box>
          </geometry>
        </collision>
      </link>
    </model>
    <!--
      Плагины для движения робота с клавиатуры (TriggeredPublisher).
      При нажатии определённых клавиш (16777234, 16777235 и т.д.) 
      публикуется Twist на топик /cmd_vel.
    -->
    <!-- Moving Left-->
    <plugin filename="gz-sim-triggered-publisher-system" name="gz::sim::systems::TriggeredPublisher">
      <input type="gz.msgs.Int32" topic="/keyboard/keypress">
        <match field="data">16777234</match>
      </input>
      <output type="gz.msgs.Twist" topic="/cmd_vel">
        linear: {x: 0.0}, angular: {z: 0.5}
      </output>
    </plugin>

    <!-- Moving Forward-->
    <plugin filename="gz-sim-triggered-publisher-system" name="gz::sim::systems::TriggeredPublisher">
      <input type="gz.msgs.Int32" topic="/keyboard/keypress">
        <match field="data">16777235</match>
      </input>
      <output type="gz.msgs.Twist" topic="/cmd_vel">
        linear: {x: 0.5}, angular: {z: 0.0}
      </output>
    </plugin>

    <!-- Moving Right-->
    <plugin filename="gz-sim-triggered-publisher-system" name="gz::sim::systems::TriggeredPublisher">
      <input type="gz.msgs.Int32" topic="/keyboard/keypress">
        <match field="data">16777236</match>
      </input>
      <output type="gz.msgs.Twist" topic="/cmd_vel">
        linear: {x: 0.0}, angular: {z: -0.5}
      </output>
    </plugin>

    <!-- Moving Backward-->
    <plugin filename="gz-sim-triggered-publisher-system" name="gz::sim::systems::TriggeredPublisher">
      <input type="gz.msgs.Int32" topic="/keyboard/keypress">
        <match field="data">16777237</match>
      </input>
      <output type="gz.msgs.Twist" topic="/cmd_vel">
        linear: {x: -0.5}, angular: {z: 0.0}
      </output>
    </plugin>

  </world>
</sdf>

